Workbook

Sheet Read Me
B1: ROSSBY FINANCIAL
B2: Multi-Office CVP (Cost-Volume-Profit) & Breakeven Model
B4: What this model answers
B5: How many advisor offices does Rossby need to cover its firm-wide fixed costs, and how does that breakeven move as we add offices? It also tracks every existing office's contribution to the firm.
B7: How the tabs fit together
B8: 1. Assumptions & Fixed Costs — set the annualization factor and toggle which P&L lines are ongoing fixed costs. Produces Total Go-Forward Annual Fixed Costs. Holds the editable pricing-engine tiers.
B9: 2. Office Register — every office (18 existing, preloaded from the 2026 Billing book) with its revenue to Rossby and contribution. Add prospects in the blank rows.
B10: 3. CVP Dashboard — the headline: total contribution vs fixed costs, firm net income, breakeven office count, and how the per-office breakeven bar falls as offices are added.
B11: 4. New Office Evaluator — price a prospective office off the tiered engine and see its marginal effect on firm net income and breakeven.
B13: Key definitions
B14: Contribution (per office) = Revenue to Rossby − Cost to Serve. This is what each office contributes toward covering firm fixed costs. Rossby's revenue is platform/billing revenue (base + per-account + per-advisor fees), NOT the advisory fees that pass through to advisors.
B16: Fixed Costs = Rossby's own overhead (software, payroll, rent, compliance, etc.) that does not scale one-for-one with each office. Taken from the P&L, annualized, with the paid-off debt and one-time items removed via the toggles on Tab 2.
... B31: Input cell (edit me)

Sheet Assumptions & Fixed Costs
B1: Assumptions & Fixed Costs
B3: P&L period | C3: Jan 1 – Jul 1 2026 (6 mo)
B4: Annualization factor | C4: 2 | D4: × (2 = annualize; 1 = keep 6-mo actuals)
B6: GO-FORWARD FIXED COSTS (Rossby firm overhead)
B7: Expense line | C7: 6-mo Actual | D7: Include? | E7: Recurring? | F7: Annualized | G7: Note
B8: Advertising & Marketing | C8: 15281 | D8: Y | E8: Y | F8: =C8*'Assumptions & Fixed Costs'!$C$4*IF(D8="Y",1,0) | G8: Recurring
B9: Bank Fees | C9: 3157.35 | D9: Y | E9: Y | F9: =C9*'Assumptions & Fixed Costs'!$C$4*IF(D9="Y",1,0) | G9: Recurring
B10: Contractor Expense - G&A | C10: 1272.5 | D10: Y | E10: Y | F10: =C10*'Assumptions & Fixed Costs'!$C$4*IF(D10="Y",1,0) | G10: Recurring
B11: Gifts | C11: 205.98 | D11: Y | E11: Y | F11: =C11*'Assumptions & Fixed Costs'!$C$4*IF(D11="Y",1,0) | G11: Recurring
B12: Insurance Expense | C12: 10094.85 | D12: Y | E12: Y | F12: =C12*'Assumptions & Fixed Costs'!$C$4*IF(D12="Y",1,0) | G12: Recurring
B13: Interest Expense | C13: 22936.81 | D13: N | E13: Y | F13: =C13*'Assumptions & Fixed Costs'!$C$4*IF(D13="Y",1,0) | G13: REMOVE - debt paid off (gone from books)
B14: Licensing Fees | C14: 2686 | D14: Y | E14: Y | F14: =C14*'Assumptions & Fixed Costs'!$C$4*IF(D14="Y",1,0) | G14: Recurring
B15: Meals & Entertainment | C15: 1392.34 | D15: Y | E15: Y | F15: =C15*'Assumptions & Fixed Costs'!$C$4*IF(D15="Y",1,0) | G15: Recurring
B16: Office Expenses | C16: 616.47 | D16: Y | E16: Y | F16: =C16*'Assumptions & Fixed Costs'!$C$4*IF(D16="Y",1,0) | G16: Recurring
B17: Payroll Expenses (401k, taxes, wages) | C17: 91284.53 | D17: Y | E17: Y | F17: =C17*'Assumptions & Fixed Costs'!$C$4*IF(D17="Y",1,0) | G17: Recurring - scales in steps
B18: Professional Services (Legal + Tax) | C18: 4410 | D18: Y | E18: Y | F18: =C18*'Assumptions & Fixed Costs'!$C$4*IF(D18="Y",1,0) | G18: Recurring
B19: Public Relations Expense | C19: 1900 | D19: Y | E19: Y | F19: =C19*'Assumptions & Fixed Costs'!$C$4*IF(D19="Y",1,0) | G19: Recurring
... B27: Utilities Expense | C27: 4312.95 | D27: Y | E27: Y | F27: =C27*'Assumptions & Fixed Costs'!$C$4*IF(D27="Y",1,0) | G27: Recurring
B28: TOTAL GO-FORWARD ANNUAL FIXED COSTS | F28: =SUM(F8:F27)
B29: (memo) 6-mo included subtotal | F29: =SUMPRODUCT((D8:D27="Y")*C8:C27)
B32: PRICING ENGINE (revenue to Rossby per office — editable list-price grid)
B33: Base platform fee — Access model | C33: 20000
B34: Base platform fee — Founders model | C34: 25000
B36: Per-account rate ($/account/month)
B37: Min accounts (>=) | C37: $/acct/mo
B38: 0 | C38: 7
B39: 101 | C39: 6
B40: 501 | C40: 5
B41: 1301 | C41: 4
B42: 2101 | C42: 3
B43: 3401 | C43: 2
B44: 5501 | C44: 1
B45: 10001 | C45: 0.75
B47: Per additional-advisor fee ($/extra advisor/year)
B48: Min advisors (>=) | C48: $/extra advisor/yr
B49: 0 | C49: 7500
B50: 4 | C50: 5000
B51: 6 | C51: 2500
B52: 9 | C52: 1500
B53: 14 | C53: 1000
...

Sheet Office Register
B1: Office Register
B2: Existing offices preloaded from the 2026 Billing book. Add prospects in the blank rows below.
B4: Office | C4: Status | D4: Model | E4: Base Fee | F4: Accounts | G4: IARs | H4: Per-Acct $/mo | I4: Per-Advisor $ | J4: Discount % | K4: Actual Annual Rev | L4: Modeled (List) | M4: Rev Used | N4: Cost to Serve | O4: Contribution
B5: Red Oak | C5: Existing | D5: Founders | E5: 25000 | G5: 1 | I5: 0 | J5: 0 | K5: 25000 | L5: =IF(B5="","",IF(N(F5)=0,IF(E5="",IF(D5="Founders",'Assumptions & Fixed Costs'!$C$34,'Assumptions & Fixed Costs'!$C$33),E5)+MAX(N(G5)-1,0)*LOOKUP(N(G5),'Assumptions & Fixed Costs'!$B$49:$B$53,'Assumptions & Fixed Costs'!$C$49:$C$53),IF(E5="",IF(D5="Founders",'Assumptions & Fixed Costs'!$C$34,'Assumptions & Fixed Costs'!$C$33),E5)+F5*LOOKUP(F5,'Assumptions & Fixed Costs'!$B$38:$B$45,'Assumptions & Fixed Costs'!$C$38:$C$45)*12+MAX(N(G5)-1,0)*LOOKUP(N(G5),'Assumptions & Fixed Costs'!$B$49:$B$53,'Assumptions & Fixed Costs'!$C$49:$C$53))) | M5: Actual | N5: 0 | O5: =IF(B5="","",IF(M5="Modeled",L5,IF(N(K5)>0,K5,L5))-N(N5))
B6: Life Strategies | C6: Existing | D6: Founders | E6: 25000 | G6: 2 | I6: 0 | J6: 0 | K6: 25000 | L6: =IF(B6="","",IF(N(F6)=0,IF(E6="",IF(D6="Founders",'Assumptions & Fixed Costs'!$C$34,'Assumptions & Fixed Costs'!$C$33),E6)+MAX(N(G6)-1,0)*LOOKUP(N(G6),'Assumptions & Fixed Costs'!$B$49:$B$53,'Assumptions & Fixed Costs'!$C$49:$C$53),IF(E6="",IF(D6="Founders",'Assumptions & Fixed Costs'!$C$34,'Assumptions & Fixed Costs'!$C$33),E6)+F6*LOOKUP(F6,'Assumptions & Fixed Costs'!$B$38:$B$45,'Assumptions & Fixed Costs'!$C$38:$C$45)*12+MAX(N(G6)-1,0)*LOOKUP(N(G6),'Assumptions & Fixed Costs'!$B$49:$B$53,'Assumptions & Fixed Costs'!$C$49:$C$53))) | M6: Actual | N6: 0 | O6: =IF(B6="","",IF(M6="Modeled",L6,IF(N(K6)>0,K6,L6))-N(N6))
B7: EViE | C7: Existing | D7: Founders | E7: 25000 | G7: 2 | I7: 5000 | J7: 0 | K7: 30000 | L7: =IF(B7="","",IF(N(F7)=0,IF(E7="",IF(D7="Founders",'Assumptions & Fixed Costs'!$C$34,'Assumptions & Fixed Costs'!$C$33),E7)+MAX(N(G7)-1,0)*LOOKUP(N(G7),'Assumptions & Fixed Costs'!$B$49:$B$53,'Assumptions & Fixed Costs'!$C$49:$C$53),IF(E7="",IF(D7="Founders",'Assumptions & Fixed Costs'!$C$34,'Assumptions & Fixed Costs'!$C$33),E7)+F7*LOOKUP(F7,'Assumptions & Fixed Costs'!$B$38:$B$45,'Assumptions & Fixed Costs'!$C$38:$C$45)*12+MAX(N(G7)-1,0)*LOOKUP(N(G7),'Assumptions & Fixed Costs'!$B$49:$B$53,'Assumptions & Fixed Costs'!$C$49:$C$53))) | M7: Actual | N7: 0 | O7: =IF(B7="","",IF(M7="Modeled",L7,IF(N(K7)>0,K7,L7))-N(N7))
B8: Florio | C8: Existing | D8: Founders | E8: 25000 | G8: 1 | I8: 0 | J8: 0 | K8: 25000 | L8: =IF(B8="","",IF(N(F8)=0,IF(E8="",IF(D8="Founders",'Assumptions & Fixed Costs'!$C$34,'Assumptions & Fixed Costs'!$C$33),E8)+MAX(N(G8)-1,0)*LOOKUP(N(G8),'Assumptions & Fixed Costs'!$B$49:$B$53,'Assumptions & Fixed Costs'!$C$49:$C$53),IF(E8="",IF(D8="Founders",'Assumptions & Fixed Costs'!$C$34,'Assumptions & Fixed Costs'!$C$33),E8)+F8*LOOKUP(F8,'Assumptions & Fixed Costs'!$B$38:$B$45,'Assumptions & Fixed Costs'!$C$38:$C$45)*12+MAX(N(G8)-1,0)*LOOKUP(N(G8),'Assumptions & Fixed Costs'!$B$49:$B$53,'Assumptions & Fixed Costs'!$C$49:$C$53))) | M8: Actual | N8: 0 | O8: =IF(B8="","",IF(M8="Modeled",L8,IF(N(K8)>0,K8,L8))-N(N8))
B9: Toler | C9: Existing | D9: Access | E9: 20000 | F9: 854 | G9: 5 | H9: 4 | I9: 20000 | J9: 0 | K9: 80992 | L9: =IF(B9="","",IF(N(F9)=0,IF(E9="",IF(D9="Founders",'Assumptions & Fixed Costs'!$C$34,'Assumptions & Fixed Costs'!$C$33),E9)+MAX(N(G9)-1,0)*LOOKUP(N(G9),'Assumptions & Fixed Costs'!$B$49:$B$53,'Assumptions & Fixed Costs'!$C$49:$C$53),IF(E9="",IF(D9="Founders",'Assumptions & Fixed Costs'!$C$34,'Assumptions & Fixed Costs'!$C$33),E9)+F9*LOOKUP(F9,'Assumptions & Fixed Costs'!$B$38:$B$45,'Assumptions & Fixed Costs'!$C$38:$C$45)*12+MAX(N(G9)-1,0)*LOOKUP(N(G9),'Assumptions & Fixed Costs'!$B$49:$B$53,'Assumptions & Fixed Costs'!$C$49:$C$53))) | M9: Actual | N9: 0 | O9: =IF(B9="","",IF(M9="Modeled",L9,IF(N(K9)>0,K9,L9))-N(N9))
B10: RMRG | C10: Existing | D10: Access | E10: 20000 | F10: 124 | G10: 2 | H10: 5 | I10: 7500 | J10: 0.2 | K10: 27952 | L10: =IF(B10="","",IF(N(F10)=0,IF(E10="",IF(D10="Founders",'Assumptions & Fixed Costs'!$C$34,'Assumptions & Fixed Costs'!$C$33),E10)+MAX(N(G10)-1,0)*LOOKUP(N(G10),'Assumptions & Fixed Costs'!$B$49:$B$53,'Assumptions & Fixed Costs'!$C$49:$C$53),IF(E10="",IF(D10="Founders",'Assumptions & Fixed Costs'!$C$34,'Assumptions & Fixed Costs'!$C$33),E10)+F10*LOOKUP(F10,'Assumptions & Fixed Costs'!$B$38:$B$45,'Assumptions & Fixed Costs'!$C$38:$C$45)*12+MAX(N(G10)-1,0)*LOOKUP(N(G10),'Assumptions & Fixed Costs'!$B$49:$B$53,'Assumptions & Fixed Costs'!$C$49:$C$53))) | M10: Actual | N10: 0 | O10: =IF(B10="","",IF(M10="Modeled",L10,IF(N(K10)>0,K10,L10))-N(N10))
B11: Trucess | C11: Existing | D11: Access | E11: 15000 | F11: 130 | G11: 1 | H11: 5 | I11: 0 | J11: 0 | K11: 22800 | L11: =IF(B11="","",IF(N(F11)=0,IF(E11="",IF(D11="Founders",'Assumptions & Fixed Costs'!$C$34,'Assumptions & Fixed Costs'!$C$33),E11)+MAX(N(G11)-1,0)*LOOKUP(N(G11),'Assumptions & Fixed Costs'!$B$49:$B$53,'Assumptions & Fixed Costs'!$C$49:$C$53),IF(E11="",IF(D11="Founders",'Assumptions & Fixed Costs'!$C$34,'Assumptions & Fixed Costs'!$C$33),E11)+F11*LOOKUP(F11,'Assumptions & Fixed Costs'!$B$38:$B$45,'Assumptions & Fixed Costs'!$C$38:$C$45)*12+MAX(N(G11)-1,0)*LOOKUP(N(G11),'Assumptions & Fixed Costs'!$B$49:$B$53,'Assumptions & Fixed Costs'!$C$49:$C$53))) | M11: Actual | N11: 0 | O11: =IF(B11="","",IF(M11="Modeled",L11,IF(N(K11)>0,K11,L11))-N(N11))
B12: Reymar Wealth | C12: Existing | D12: Access | E12: 20000 | F12: 131 | G12: 1 | H12: 5 | I12: 0 | J12: 0 | K12: 27860 | L12: =IF(B12="","",IF(N(F12)=0,IF(E12="",IF(D12="Founders",'Assumptions & Fixed Costs'!$C$34,'Assumptions & Fixed Costs'!$C$33),E12)+MAX(N(G12)-1,0)*LOOKUP(N(G12),'Assumptions & Fixed Costs'!$B$49:$B$53,'Assumptions & Fixed Costs'!$C$49:$C$53),IF(E12="",IF(D12="Founders",'Assumptions & Fixed Costs'!$C$34,'Assumptions & Fixed Costs'!$C$33),E12)+F12*LOOKUP(F12,'Assumptions & Fixed Costs'!$B$38:$B$45,'Assumptions & Fixed Costs'!$C$38:$C$45)*12+MAX(N(G12)-1,0)*LOOKUP(N(G12),'Assumptions & Fixed Costs'!$B$49:$B$53,'Assumptions & Fixed Costs'!$C$49:$C$53))) | M12: Actual | N12: 0 | O12: =IF(B12="","",IF(M12="Modeled",L12,IF(N(K12)>0,K12,L12))-N(N12))
B13: Alan R. Joyce Co. | C13: Existing | D13: Access | E13: 20000 | F13: 14 | G13: 1 | H13: 6 | I13: 0 | J13: 0 | K13: 21008 | L13: =IF(B13="","",IF(N(F13)=0,IF(E13="",IF(D13="Founders",'Assumptions & Fixed Costs'!$C$34,'Assumptions & Fixed Costs'!$C$33),E13)+MAX(N(G13)-1,0)*LOOKUP(N(G13),'Assumptions & Fixed Costs'!$B$49:$B$53,'Assumptions & Fixed Costs'!$C$49:$C$53),IF(E13="",IF(D13="Founders",'Assumptions & Fixed Costs'!$C$34,'Assumptions & Fixed Costs'!$C$33),E13)+F13*LOOKUP(F13,'Assumptions & Fixed Costs'!$B$38:$B$45,'Assumptions & Fixed Costs'!$C$38:$C$45)*12+MAX(N(G13)-1,0)*LOOKUP(N(G13),'Assumptions & Fixed Costs'!$B$49:$B$53,'Assumptions & Fixed Costs'!$C$49:$C$53))) | M13: Actual | N13: 0 | O13: =IF(B13="","",IF(M13="Modeled",L13,IF(N(K13)>0,K13,L13))-N(N13))
B14: OSBORN Wealth | C14: Existing | D14: Access | E14: 20000 | F14: 197 | G14: 2 | H14: 4.0609137 | I14: 7500 | J14: 0 | K14: 37100 | L14: =IF(B14="","",IF(N(F14)=0,IF(E14="",IF(D14="Founders",'Assumptions & Fixed Costs'!$C$34,'Assumptions & Fixed Costs'!$C$33),E14)+MAX(N(G14)-1,0)*LOOKUP(N(G14),'Assumptions & Fixed Costs'!$B$49:$B$53,'Assumptions & Fixed Costs'!$C$49:$C$53),IF(E14="",IF(D14="Founders",'Assumptions & Fixed Costs'!$C$34,'Assumptions & Fixed Costs'!$C$33),E14)+F14*LOOKUP(F14,'Assumptions & Fixed Costs'!$B$38:$B$45,'Assumptions & Fixed Costs'!$C$38:$C$45)*12+MAX(N(G14)-1,0)*LOOKUP(N(G14),'Assumptions & Fixed Costs'!$B$49:$B$53,'Assumptions & Fixed Costs'!$C$49:$C$53))) | M14: Actual | N14: 0 | O14: =IF(B14="","",IF(M14="Modeled",L14,IF(N(K14)>0,K14,L14))-N(N14))
B15: Windward Financial | C15: Existing | D15: Access | E15: 20000 | F15: 119 | G15: 1 | H15: 5 | I15: 0 | J15: 0 | K15: 27140 | L15: =IF(B15="","",IF(N(F15)=0,IF(E15="",IF(D15="Founders",'Assumptions & Fixed Costs'!$C$34,'Assumptions & Fixed Costs'!$C$33),E15)+MAX(N(G15)-1,0)*LOOKUP(N(G15),'Assumptions & Fixed Costs'!$B$49:$B$53,'Assumptions & Fixed Costs'!$C$49:$C$53),IF(E15="",IF(D15="Founders",'Assumptions & Fixed Costs'!$C$34,'Assumptions & Fixed Costs'!$C$33),E15)+F15*LOOKUP(F15,'Assumptions & Fixed Costs'!$B$38:$B$45,'Assumptions & Fixed Costs'!$C$38:$C$45)*12+MAX(N(G15)-1,0)*LOOKUP(N(G15),'Assumptions & Fixed Costs'!$B$49:$B$53,'Assumptions & Fixed Costs'!$C$49:$C$53))) | M15: Actual | N15: 0 | O15: =IF(B15="","",IF(M15="Modeled",L15,IF(N(K15)>0,K15,L15))-N(N15))
B16: Financial Strategies | C16: Existing | D16: Access | E16: 20000 | F16: 319 | G16: 1 | H16: 5 | I16: 0 | J16: 0 | K16: 39140 | L16: =IF(B16="","",IF(N(F16)=0,IF(E16="",IF(D16="Founders",'Assumptions & Fixed Costs'!$C$34,'Assumptions & Fixed Costs'!$C$33),E16)+MAX(N(G16)-1,0)*LOOKUP(N(G16),'Assumptions & Fixed Costs'!$B$49:$B$53,'Assumptions & Fixed Costs'!$C$49:$C$53),IF(E16="",IF(D16="Founders",'Assumptions & Fixed Costs'!$C$34,'Assumptions & Fixed Costs'!$C$33),E16)+F16*LOOKUP(F16,'Assumptions & Fixed Costs'!$B$38:$B$45,'Assumptions & Fixed Costs'!$C$38:$C$45)*12+MAX(N(G16)-1,0)*LOOKUP(N(G16),'Assumptions & Fixed Costs'!$B$49:$B$53,'Assumptions & Fixed Costs'!$C$49:$C$53))) | M16: Actual | N16: 0 | O16: =IF(B16="","",IF(M16="Modeled",L16,IF(N(K16)>0,K16,L16))-N(N16))
B17: Prarie Oak | C17: Existing | D17: Access | E17: 20000 | F17: 231 | G17: 2 | H17: 5 | I17: 7500 | J17: 0 | K17: 41360 | L17: =IF(B17="","",IF(N(F17)=0,IF(E17="",IF(D17="Founders",'Assumptions & Fixed Costs'!$C$34,'Assumptions & Fixed Costs'!$C$33),E17)+MAX(N(G17)-1,0)*LOOKUP(N(G17),'Assumptions & Fixed Costs'!$B$49:$B$53,'Assumptions & Fixed Costs'!$C$49:$C$53),IF(E17="",IF(D17="Founders",'Assumptions & Fixed Costs'!$C$34,'Assumptions & Fixed Costs'!$C$33),E17)+F17*LOOKUP(F17,'Assumptions & Fixed Costs'!$B$38:$B$45,'Assumptions & Fixed Costs'!$C$38:$C$45)*12+MAX(N(G17)-1,0)*LOOKUP(N(G17),'Assumptions & Fixed Costs'!$B$49:$B$53,'Assumptions & Fixed Costs'!$C$49:$C$53))) | M17: Actual | N17: 0 | O17: =IF(B17="","",IF(M17="Modeled",L17,IF(N(K17)>0,K17,L17))-N(N17))
B18: Sequence Wealth | C18: Existing | D18: Access | E18: 20000 | F18: 59 | G18: 1 | H18: 6 | I18: 0 | J18: 0 | K18: 24248 | L18: =IF(B18="","",IF(N(F18)=0,IF(E18="",IF(D18="Founders",'Assumptions & Fixed Costs'!$C$34,'Assumptions & Fixed Costs'!$C$33),E18)+MAX(N(G18)-1,0)*LOOKUP(N(G18),'Assumptions & Fixed Costs'!$B$49:$B$53,'Assumptions & Fixed Costs'!$C$49:$C$53),IF(E18="",IF(D18="Founders",'Assumptions & Fixed Costs'!$C$34,'Assumptions & Fixed Costs'!$C$33),E18)+F18*LOOKUP(F18,'Assumptions & Fixed Costs'!$B$38:$B$45,'Assumptions & Fixed Costs'!$C$38:$C$45)*12+MAX(N(G18)-1,0)*LOOKUP(N(G18),'Assumptions & Fixed Costs'!$B$49:$B$53,'Assumptions & Fixed Costs'!$C$49:$C$53))) | M18: Actual | N18: 0 | O18: =IF(B18="","",IF(M18="Modeled",L18,IF(N(K18)>0,K18,L18))-N(N18))
B19: Oak Stream Investments | C19: Existing | D19: Access | E19: 20000 | F19: 88 | G19: 1 | H19: 7 | I19: 0 | J19: 0 | K19: 27392 | L19: =IF(B19="","",IF(N(F19)=0,IF(E19="",IF(D19="Founders",'Assumptions & Fixed Costs'!$C$34,'Assumptions & Fixed Costs'!$C$33),E19)+MAX(N(G19)-1,0)*LOOKUP(N(G19),'Assumptions & Fixed Costs'!$B$49:$B$53,'Assumptions & Fixed Costs'!$C$49:$C$53),IF(E19="",IF(D19="Founders",'Assumptions & Fixed Costs'!$C$34,'Assumptions & Fixed Costs'!$C$33),E19)+F19*LOOKUP(F19,'Assumptions & Fixed Costs'!$B$38:$B$45,'Assumptions & Fixed Costs'!$C$38:$C$45)*12+MAX(N(G19)-1,0)*LOOKUP(N(G19),'Assumptions & Fixed Costs'!$B$49:$B$53,'Assumptions & Fixed Costs'!$C$49:$C$53))) | M19: Actual | N19: 0 | O19: =IF(B19="","",IF(M19="Modeled",L19,IF(N(K19)>0,K19,L19))-N(N19))
B20: Tribox | C20: Existing | D20: Access | E20: 20000 | F20: 261 | G20: 2 | H20: 6 | I20: 7500 | J20: 0 | K20: 46292 | L20: =IF(B20="","",IF(N(F20)=0,IF(E20="",IF(D20="Founders",'Assumptions & Fixed Costs'!$C$34,'Assumptions & Fixed Costs'!$C$33),E20)+MAX(N(G20)-1,0)*LOOKUP(N(G20),'Assumptions & Fixed Costs'!$B$49:$B$53,'Assumptions & Fixed Costs'!$C$49:$C$53),IF(E20="",IF(D20="Founders",'Assumptions & Fixed Costs'!$C$34,'Assumptions & Fixed Costs'!$C$33),E20)+F20*LOOKUP(F20,'Assumptions & Fixed Costs'!$B$38:$B$45,'Assumptions & Fixed Costs'!$C$38:$C$45)*12+MAX(N(G20)-1,0)*LOOKUP(N(G20),'Assumptions & Fixed Costs'!$B$49:$B$53,'Assumptions & Fixed Costs'!$C$49:$C$53))) | M20: Actual | N20: 0 | O20: =IF(B20="","",IF(M20="Modeled",L20,IF(N(K20)>0,K20,L20))-N(N20))
... B22: AP Financial | C22: Existing | D22: Access | E22: 20000 | F22: 20 | G22: 1 | H22: 7 | I22: 0 | J22: 0 | K22: 21680 | L22: =IF(B22="","",IF(N(F22)=0,IF(E22="",IF(D22="Founders",'Assumptions & Fixed Costs'!$C$34,'Assumptions & Fixed Costs'!$C$33),E22)+MAX(N(G22)-1,0)*LOOKUP(N(G22),'Assumptions & Fixed Costs'!$B$49:$B$53,'Assumptions & Fixed Costs'!$C$49:$C$53),IF(E22="",IF(D22="Founders",'Assumptions & Fixed Costs'!$C$34,'Assumptions & Fixed Costs'!$C$33),E22)+F22*LOOKUP(F22,'Assumptions & Fixed Costs'!$B$38:$B$45,'Assumptions & Fixed Costs'!$C$38:$C$45)*12+MAX(N(G22)-1,0)*LOOKUP(N(G22),'Assumptions & Fixed Costs'!$B$49:$B$53,'Assumptions & Fixed Costs'!$C$49:$C$53))) | M22: Actual | N22: 0 | O22: =IF(B22="","",IF(M22="Modeled",L22,IF(N(K22)>0,K22,L22))-N(N22))
L23: =IF(B23="","",IF(N(F23)=0,IF(E23="",IF(D23="Founders",'Assumptions & Fixed Costs'!$C$34,'Assumptions & Fixed Costs'!$C$33),E23)+MAX(N(G23)-1,0)*LOOKUP(N(G23),'Assumptions & Fixed Costs'!$B$49:$B$53,'Assumptions & Fixed Costs'!$C$49:$C$53),IF(E23="",IF(D23="Founders",'Assumptions & Fixed Costs'!$C$34,'Assumptions & Fixed Costs'!$C$33),E23)+F23*LOOKUP(F23,'Assumptions & Fixed Costs'!$B$38:$B$45,'Assumptions & Fixed Costs'!$C$38:$C$45)*12+MAX(N(G23)-1,0)*LOOKUP(N(G23),'Assumptions & Fixed Costs'!$B$49:$B$53,'Assumptions & Fixed Costs'!$C$49:$C$53))) | M23: Modeled | O23: =IF(B23="","",IF(M23="Modeled",L23,IF(N(K23)>0,K23,L23))-N(N23))
L24: =IF(B24="","",IF(N(F24)=0,IF(E24="",IF(D24="Founders",'Assumptions & Fixed Costs'!$C$34,'Assumptions & Fixed Costs'!$C$33),E24)+MAX(N(G24)-1,0)*LOOKUP(N(G24),'Assumptions & Fixed Costs'!$B$49:$B$53,'Assumptions & Fixed Costs'!$C$49:$C$53),IF(E24="",IF(D24="Founders",'Assumptions & Fixed Costs'!$C$34,'Assumptions & Fixed Costs'!$C$33),E24)+F24*LOOKUP(F24,'Assumptions & Fixed Costs'!$B$38:$B$45,'Assumptions & Fixed Costs'!$C$38:$C$45)*12+MAX(N(G24)-1,0)*LOOKUP(N(G24),'Assumptions & Fixed Costs'!$B$49:$B$53,'Assumptions & Fixed Costs'!$C$49:$C$53))) | M24: Modeled | O24: =IF(B24="","",IF(M24="Modeled",L24,IF(N(K24)>0,K24,L24))-N(N24))
L25: =IF(B25="","",IF(N(F25)=0,IF(E25="",IF(D25="Founders",'Assumptions & Fixed Costs'!$C$34,'Assumptions & Fixed Costs'!$C$33),E25)+MAX(N(G25)-1,0)*LOOKUP(N(G25),'Assumptions & Fixed Costs'!$B$49:$B$53,'Assumptions & Fixed Costs'!$C$49:$C$53),IF(E25="",IF(D25="Founders",'Assumptions & Fixed Costs'!$C$34,'Assumptions & Fixed Costs'!$C$33),E25)+F25*LOOKUP(F25,'Assumptions & Fixed Costs'!$B$38:$B$45,'Assumptions & Fixed Costs'!$C$38:$C$45)*12+MAX(N(G25)-1,0)*LOOKUP(N(G25),'Assumptions & Fixed Costs'!$B$49:$B$53,'Assumptions & Fixed Costs'!$C$49:$C$53))) | M25: Modeled | O25: =IF(B25="","",IF(M25="Modeled",L25,IF(N(K25)>0,K25,L25))-N(N25))
L26: =IF(B26="","",IF(N(F26)=0,IF(E26="",IF(D26="Founders",'Assumptions & Fixed Costs'!$C$34,'Assumptions & Fixed Costs'!$C$33),E26)+MAX(N(G26)-1,0)*LOOKUP(N(G26),'Assumptions & Fixed Costs'!$B$49:$B$53,'Assumptions & Fixed Costs'!$C$49:$C$53),IF(E26="",IF(D26="Founders",'Assumptions & Fixed Costs'!$C$34,'Assumptions & Fixed Costs'!$C$33),E26)+F26*LOOKUP(F26,'Assumptions & Fixed Costs'!$B$38:$B$45,'Assumptions & Fixed Costs'!$C$38:$C$45)*12+MAX(N(G26)-1,0)*LOOKUP(N(G26),'Assumptions & Fixed Costs'!$B$49:$B$53,'Assumptions & Fixed Costs'!$C$49:$C$53))) | M26: Modeled | O26: =IF(B26="","",IF(M26="Modeled",L26,IF(N(K26)>0,K26,L26))-N(N26))
L27: =IF(B27="","",IF(N(F27)=0,IF(E27="",IF(D27="Founders",'Assumptions & Fixed Costs'!$C$34,'Assumptions & Fixed Costs'!$C$33),E27)+MAX(N(G27)-1,0)*LOOKUP(N(G27),'Assumptions & Fixed Costs'!$B$49:$B$53,'Assumptions & Fixed Costs'!$C$49:$C$53),IF(E27="",IF(D27="Founders",'Assumptions & Fixed Costs'!$C$34,'Assumptions & Fixed Costs'!$C$33),E27)+F27*LOOKUP(F27,'Assumptions & Fixed Costs'!$B$38:$B$45,'Assumptions & Fixed Costs'!$C$38:$C$45)*12+MAX(N(G27)-1,0)*LOOKUP(N(G27),'Assumptions & Fixed Costs'!$B$49:$B$53,'Assumptions & Fixed Costs'!$C$49:$C$53))) | M27: Modeled | O27: =IF(B27="","",IF(M27="Modeled",L27,IF(N(K27)>0,K27,L27))-N(N27))
L28: =IF(B28="","",IF(N(F28)=0,IF(E28="",IF(D28="Founders",'Assumptions & Fixed Costs'!$C$34,'Assumptions & Fixed Costs'!$C$33),E28)+MAX(N(G28)-1,0)*LOOKUP(N(G28),'Assumptions & Fixed Costs'!$B$49:$B$53,'Assumptions & Fixed Costs'!$C$49:$C$53),IF(E28="",IF(D28="Founders",'Assumptions & Fixed Costs'!$C$34,'Assumptions & Fixed Costs'!$C$33),E28)+F28*LOOKUP(F28,'Assumptions & Fixed Costs'!$B$38:$B$45,'Assumptions & Fixed Costs'!$C$38:$C$45)*12+MAX(N(G28)-1,0)*LOOKUP(N(G28),'Assumptions & Fixed Costs'!$B$49:$B$53,'Assumptions & Fixed Costs'!$C$49:$C$53))) | M28: Modeled | O28: =IF(B28="","",IF(M28="Modeled",L28,IF(N(K28)>0,K28,L28))-N(N28))
L29: =IF(B29="","",IF(N(F29)=0,IF(E29="",IF(D29="Founders",'Assumptions & Fixed Costs'!$C$34,'Assumptions & Fixed Costs'!$C$33),E29)+MAX(N(G29)-1,0)*LOOKUP(N(G29),'Assumptions & Fixed Costs'!$B$49:$B$53,'Assumptions & Fixed Costs'!$C$49:$C$53),IF(E29="",IF(D29="Founders",'Assumptions & Fixed Costs'!$C$34,'Assumptions & Fixed Costs'!$C$33),E29)+F29*LOOKUP(F29,'Assumptions & Fixed Costs'!$B$38:$B$45,'Assumptions & Fixed Costs'!$C$38:$C$45)*12+MAX(N(G29)-1,0)*LOOKUP(N(G29),'Assumptions & Fixed Costs'!$B$49:$B$53,'Assumptions & Fixed Costs'!$C$49:$C$53))) | M29: Modeled | O29: =IF(B29="","",IF(M29="Modeled",L29,IF(N(K29)>0,K29,L29))-N(N29))
L30: =IF(B30="","",IF(N(F30)=0,IF(E30="",IF(D30="Founders",'Assumptions & Fixed Costs'!$C$34,'Assumptions & Fixed Costs'!$C$33),E30)+MAX(N(G30)-1,0)*LOOKUP(N(G30),'Assumptions & Fixed Costs'!$B$49:$B$53,'Assumptions & Fixed Costs'!$C$49:$C$53),IF(E30="",IF(D30="Founders",'Assumptions & Fixed Costs'!$C$34,'Assumptions & Fixed Costs'!$C$33),E30)+F30*LOOKUP(F30,'Assumptions & Fixed Costs'!$B$38:$B$45,'Assumptions & Fixed Costs'!$C$38:$C$45)*12+MAX(N(G30)-1,0)*LOOKUP(N(G30),'Assumptions & Fixed Costs'!$B$49:$B$53,'Assumptions & Fixed Costs'!$C$49:$C$53))) | M30: Modeled | O30: =IF(B30="","",IF(M30="Modeled",L30,IF(N(K30)>0,K30,L30))-N(N30))
L31: =IF(B31="","",IF(N(F31)=0,IF(E31="",IF(D31="Founders",'Assumptions & Fixed Costs'!$C$34,'Assumptions & Fixed Costs'!$C$33),E31)+MAX(N(G31)-1,0)*LOOKUP(N(G31),'Assumptions & Fixed Costs'!$B$49:$B$53,'Assumptions & Fixed Costs'!$C$49:$C$53),IF(E31="",IF(D31="Founders",'Assumptions & Fixed Costs'!$C$34,'Assumptions & Fixed Costs'!$C$33),E31)+F31*LOOKUP(F31,'Assumptions & Fixed Costs'!$B$38:$B$45,'Assumptions & Fixed Costs'!$C$38:$C$45)*12+MAX(N(G31)-1,0)*LOOKUP(N(G31),'Assumptions & Fixed Costs'!$B$49:$B$53,'Assumptions & Fixed Costs'!$C$49:$C$53))) | M31: Modeled | O31: =IF(B31="","",IF(M31="Modeled",L31,IF(N(K31)>0,K31,L31))-N(N31))
L32: =IF(B32="","",IF(N(F32)=0,IF(E32="",IF(D32="Founders",'Assumptions & Fixed Costs'!$C$34,'Assumptions & Fixed Costs'!$C$33),E32)+MAX(N(G32)-1,0)*LOOKUP(N(G32),'Assumptions & Fixed Costs'!$B$49:$B$53,'Assumptions & Fixed Costs'!$C$49:$C$53),IF(E32="",IF(D32="Founders",'Assumptions & Fixed Costs'!$C$34,'Assumptions & Fixed Costs'!$C$33),E32)+F32*LOOKUP(F32,'Assumptions & Fixed Costs'!$B$38:$B$45,'Assumptions & Fixed Costs'!$C$38:$C$45)*12+MAX(N(G32)-1,0)*LOOKUP(N(G32),'Assumptions & Fixed Costs'!$B$49:$B$53,'Assumptions & Fixed Costs'!$C$49:$C$53))) | M32: Modeled | O32: =IF(B32="","",IF(M32="Modeled",L32,IF(N(K32)>0,K32,L32))-N(N32))
L33: =IF(B33="","",IF(N(F33)=0,IF(E33="",IF(D33="Founders",'Assumptions & Fixed Costs'!$C$34,'Assumptions & Fixed Costs'!$C$33),E33)+MAX(N(G33)-1,0)*LOOKUP(N(G33),'Assumptions & Fixed Costs'!$B$49:$B$53,'Assumptions & Fixed Costs'!$C$49:$C$53),IF(E33="",IF(D33="Founders",'Assumptions & Fixed Costs'!$C$34,'Assumptions & Fixed Costs'!$C$33),E33)+F33*LOOKUP(F33,'Assumptions & Fixed Costs'!$B$38:$B$45,'Assumptions & Fixed Costs'!$C$38:$C$45)*12+MAX(N(G33)-1,0)*LOOKUP(N(G33),'Assumptions & Fixed Costs'!$B$49:$B$53,'Assumptions & Fixed Costs'!$C$49:$C$53))) | M33: Modeled | O33: =IF(B33="","",IF(M33="Modeled",L33,IF(N(K33)>0,K33,L33))-N(N33))
B34: TOTALS | C34: =COUNTA(B5:B33) | F34: =SUM(F5:F33) | G34: =SUM(G5:G33) | N34: =SUM(N5:N33) | O34: =SUM(O5:O33)

Sheet CVP Dashboard
B1: CVP Dashboard & Breakeven
B3: FIRM POSITION TODAY
B4: Active offices | C4: ='Office Register'!$C$34
B5: Total annual contribution | C5: ='Office Register'!$O$34
B6: Total go-forward annual fixed costs | C6: ='Assumptions & Fixed Costs'!$F$28
B7: Firm Net Operating Income | C7: ='Office Register'!$O$34-'Assumptions & Fixed Costs'!$F$28
B8: Average contribution per office | C8: =IF('Office Register'!$C$34=0,0,'Office Register'!$O$34/'Office Register'!$C$34)
B10: BREAKEVEN
B11: Breakeven # of offices (at avg contribution) | C11: =IF('CVP Dashboard'!$C$8<=0,"n/a",ROUNDUP('Assumptions & Fixed Costs'!$F$28/'CVP Dashboard'!$C$8,0))
B12: Breakeven contribution required PER OFFICE (at current count) | C12: =IF('Office Register'!$C$34=0,"n/a",'Assumptions & Fixed Costs'!$F$28/'Office Register'!$C$34)
B13: Margin of safety (offices above breakeven) | C13: =IF('CVP Dashboard'!$C$8<=0,"n/a",'Office Register'!$C$34-ROUNDUP('Assumptions & Fixed Costs'!$F$28/'CVP Dashboard'!$C$8,0))
B14: Contribution margin coverage (contribution ÷ fixed) | C14: =IF('Assumptions & Fixed Costs'!$F$28=0,"n/a",'Office Register'!$O$34/'Assumptions & Fixed Costs'!$F$28)
B16: The per-office breakeven requirement (row 12) FALLS as offices are added — fixed costs are shared across more offices. The schedule below shows contribution stacking against the fixed-cost line.
E19: BREAKEVEN-SHIFT SCHEDULE (as offices are added, at avg contribution)
E20: # Offices | F20: Cumulative Contribution | G20: Fixed Costs | H20: Net Income
E21: 1 | F21: =E21*'CVP Dashboard'!$C$8 | G21: ='Assumptions & Fixed Costs'!$F$28 | H21: =F21-G21
E22: 2 | F22: =E22*'CVP Dashboard'!$C$8 | G22: ='Assumptions & Fixed Costs'!$F$28 | H22: =F22-G22
E23: 3 | F23: =E23*'CVP Dashboard'!$C$8 | G23: ='Assumptions & Fixed Costs'!$F$28 | H23: =F23-G23
E24: 4 | F24: =E24*'CVP Dashboard'!$C$8 | G24: ='Assumptions & Fixed Costs'!$F$28 | H24: =F24-G24
E25: 5 | F25: =E25*'CVP Dashboard'!$C$8 | G25: ='Assumptions & Fixed Costs'!$F$28 | H25: =F25-G25
E26: 6 | F26: =E26*'CVP Dashboard'!$C$8 | G26: ='Assumptions & Fixed Costs'!$F$28 | H26: =F26-G26
E27: 7 | F27: =E27*'CVP Dashboard'!$C$8 | G27: ='Assumptions & Fixed Costs'!$F$28 | H27: =F27-G27
E28: 8 | F28: =E28*'CVP Dashboard'!$C$8 | G28: ='Assumptions & Fixed Costs'!$F$28 | H28: =F28-G28
E29: 9 | F29: =E29*'CVP Dashboard'!$C$8 | G29: ='Assumptions & Fixed Costs'!$F$28 | H29: =F29-G29
E30: 10 | F30: =E30*'CVP Dashboard'!$C$8 | G30: ='Assumptions & Fixed Costs'!$F$28 | H30: =F30-G30
E31: 11 | F31: =E31*'CVP Dashboard'!$C$8 | G31: ='Assumptions & Fixed Costs'!$F$28 | H31: =F31-G31
E32: 12 | F32: =E32*'CVP Dashboard'!$C$8 | G32: ='Assumptions & Fixed Costs'!$F$28 | H32: =F32-G32
... E50: 30 | F50: =E50*'CVP Dashboard'!$C$8 | G50: ='Assumptions & Fixed Costs'!$F$28 | H50: =F50-G50

Sheet New Office Evaluator
B1: New Office Evaluator
B2: Enter a prospective office to price it off the tiered engine and see its marginal impact.
B4: PROSPECT INPUTS
B5: Model (Access / Founders) | C5: Access
B6: Base fee (blank = use model default)
B7: Number of accounts | C7: 150
B8: Number of IARs (advisors) | C8: 1
B9: Cost to serve (annual, variable) | C9: 0
B11: PRICING & CONTRIBUTION
B12: Base platform fee | C12: =IF(C6="",IF(C5="Founders",'Assumptions & Fixed Costs'!$C$34,'Assumptions & Fixed Costs'!$C$33),C6)
B13: Per-account revenue (annual) | C13: =IF(N(C7)=0,0,C7*LOOKUP(C7,'Assumptions & Fixed Costs'!$B$38:$B$45,'Assumptions & Fixed Costs'!$C$38:$C$45)*12)
B14: Per-advisor revenue (annual) | C14: =MAX(N(C8)-1,0)*LOOKUP(N(C8),'Assumptions & Fixed Costs'!$B$49:$B$53,'Assumptions & Fixed Costs'!$C$49:$C$53)
B15: Total revenue to Rossby | C15: =IF(C6="",IF(C5="Founders",'Assumptions & Fixed Costs'!$C$34,'Assumptions & Fixed Costs'!$C$33),C6)+IF(N(C7)=0,0,C7*LOOKUP(C7,'Assumptions & Fixed Costs'!$B$38:$B$45,'Assumptions & Fixed Costs'!$C$38:$C$45)*12)+MAX(N(C8)-1,0)*LOOKUP(N(C8),'Assumptions & Fixed Costs'!$B$49:$B$53,'Assumptions & Fixed Costs'!$C$49:$C$53)
B16: Contribution (revenue − cost to serve) | C16: =IF(C6="",IF(C5="Founders",'Assumptions & Fixed Costs'!$C$34,'Assumptions & Fixed Costs'!$C$33),C6)+IF(N(C7)=0,0,C7*LOOKUP(C7,'Assumptions & Fixed Costs'!$B$38:$B$45,'Assumptions & Fixed Costs'!$C$38:$C$45)*12)+MAX(N(C8)-1,0)*LOOKUP(N(C8),'Assumptions & Fixed Costs'!$B$49:$B$53,'Assumptions & Fixed Costs'!$C$49:$C$53)-N(C9)
B18: MARGINAL IMPACT ON FIRM
B19: Firm net income BEFORE this office | C19: ='CVP Dashboard'!$C$7
B20: Firm net income AFTER this office | C20: ='CVP Dashboard'!$C$7+'New Office Evaluator'!$C$16
B21: Change in net income | C21: ='New Office Evaluator'!$C$16
B22: Offices after adding this one | C22: ='Office Register'!$C$34+1
B24: Because Rossby is already near breakeven, most of a new office's contribution flows straight to net income. Add the office to the Register (Tab 3) to make it permanent.
